2025-03-16 20:29:17,540 - utils - ERROR - Error: <html>
<head><title>502 Bad Gateway</title></head>
<body>
<center><h1>502 Bad Gateway</h1></center>
<hr><center>cloudflare</center>
</body>
</html>, Currently Unavailable.
Traceback (most recent call last):
  File "/Users/j4-ai/workspace/OCG/utils.py", line 68, in GPT_QA_not_stream
    response = client.chat.completions.create(
               ^^^^^^^^^^^^^^^^^^^^^^^^^^^^^^^
  File "/Users/j4-ai/anaconda3/lib/python3.12/site-packages/openai/_utils/_utils.py", line 279, in wrapper
    return func(*args, **kwargs)
           ^^^^^^^^^^^^^^^^^^^^^
  File "/Users/j4-ai/anaconda3/lib/python3.12/site-packages/openai/resources/chat/completions/completions.py", line 879, in create
    return self._post(
           ^^^^^^^^^^^
  File "/Users/j4-ai/anaconda3/lib/python3.12/site-packages/openai/_base_client.py", line 1290, in post
    return cast(ResponseT, self.request(cast_to, opts, stream=stream, stream_cls=stream_cls))
                           ^^^^^^^^^^^^^^^^^^^^^^^^^^^^^^^^^^^^^^^^^^^^^^^^^^^^^^^^^^^^^^^^^
  File "/Users/j4-ai/anaconda3/lib/python3.12/site-packages/openai/_base_client.py", line 967, in request
    return self._request(
           ^^^^^^^^^^^^^^
  File "/Users/j4-ai/anaconda3/lib/python3.12/site-packages/openai/_base_client.py", line 1056, in _request
    return self._retry_request(
           ^^^^^^^^^^^^^^^^^^^^
  File "/Users/j4-ai/anaconda3/lib/python3.12/site-packages/openai/_base_client.py", line 1105, in _retry_request
    return self._request(
           ^^^^^^^^^^^^^^
  File "/Users/j4-ai/anaconda3/lib/python3.12/site-packages/openai/_base_client.py", line 1056, in _request
    return self._retry_request(
           ^^^^^^^^^^^^^^^^^^^^
  File "/Users/j4-ai/anaconda3/lib/python3.12/site-packages/openai/_base_client.py", line 1105, in _retry_request
    return self._request(
           ^^^^^^^^^^^^^^
  File "/Users/j4-ai/anaconda3/lib/python3.12/site-packages/openai/_base_client.py", line 1071, in _request
    raise self._make_status_error_from_response(err.response) from None
openai.InternalServerError: <html>
<head><title>502 Bad Gateway</title></head>
<body>
<center><h1>502 Bad Gateway</h1></center>
<hr><center>cloudflare</center>
</body>
</html>
